{"nbformat":4,"nbformat_minor":0,"metadata":{"colab":{"provenance":[]},"kernelspec":{"name":"python3","display_name":"Python 3"},"language_info":{"name":"python"}},"cells":[{"cell_type":"markdown","source":["**<center><h1>Exception</h1></center>**\n","\n","We might do some mistakes while writing program that lead to errors and when we try to run program it terminates as soon as it encounters an unhandled error.\n","\n","These errors can be broadly classified into two classes:\n","\n","- Syntax errors\n","- Logical errors (Exceptions)\n","\n","\n","**Python Syntax Errors**\n","\n","Error caused by not following the proper syntax of the language is called syntax error or parsing error.\n","\n","Let's look at one example:"],"metadata":{"id":"B-A7T3RxvA0S"}},{"cell_type":"code","source":["if a < 3\n","\n","# As shown in the example, an arrow indicates where the parser ran into the syntax error.\n","# We can notice here that a colon : is missing in the if statement."],"metadata":{"colab":{"base_uri":"https://localhost:8080/","height":131},"id":"-ZaWgzH0xS-I","executionInfo":{"status":"error","timestamp":1650974891797,"user_tz":-330,"elapsed":60,"user":{"displayName":"Santhosh Kumar","userId":"02779163303914785334"}},"outputId":"4fc11bd5-ee6a-4aa3-acfc-26c546b1ac67"},"execution_count":null,"outputs":[{"output_type":"error","ename":"SyntaxError","evalue":"ignored","traceback":["\u001b[0;36m  File \u001b[0;32m\"<ipython-input-1-1d4838d6bd33>\"\u001b[0;36m, line \u001b[0;32m1\u001b[0m\n\u001b[0;31m    if a < 3\u001b[0m\n\u001b[0m            ^\u001b[0m\n\u001b[0;31mSyntaxError\u001b[0m\u001b[0;31m:\u001b[0m invalid syntax\n"]}]},{"cell_type":"markdown","source":["**Python Logical Errors (Exceptions)**\n","\n","Logical errors or exceptions are errors  that occurs while executing the code.\n","\n","For example, they occur when we try to open a file that does not exist (FileNotFoundError), try to divide a number by zero (ZeroDivisionError), or try to import a module that does not exist (ImportError).\n","\n","Python produces an exception object if one of these runtime error happens.\n","If not handled correctly, it prints a traceback to that error and some information about how and why that error occured.\n"],"metadata":{"id":"we5UN2OnxXd4"}},{"cell_type":"markdown","source":["**Catching Exceptions in Python**\n","\n","Runtime error can be handled using `try..except` statements. The statements whcih can raise exeception can be placed insisde the `try` block. Ans code that handles exceptions can be placed insisde the except block.\n","\n","```\n","Syntax :\n","        try:\n","            # statements which can raise run time error\n","        except:\n","            # statements which can handles run time errors\n","```\n"],"metadata":{"id":"6pSGw0vkD18h"}},{"cell_type":"code","source":["# import module sys to get the type of exception\n","import sys\n","\n","randomList = ['a', 0, 2]\n","\n","for entry in randomList:\n","    try:\n","        print(\"The entry is\", entry)\n","        r = 1/int(entry)\n","        print(\"The reciprocal of\", entry, \"is\", r)\n","    except Exception as e:\n","        print(e, \"error\")\n","        print(\"Next entry.\")\n","        print()\n"],"metadata":{"colab":{"base_uri":"https://localhost:8080/"},"id":"1iDcOh6jEr-t","executionInfo":{"status":"ok","timestamp":1659510742230,"user_tz":-330,"elapsed":528,"user":{"displayName":"Santhosh Kumar","userId":"02779163303914785334"}},"outputId":"80afd8fb-196a-4ca5-8b0f-2a250808b71c"},"execution_count":null,"outputs":[{"output_type":"stream","name":"stdout","text":["The entry is a\n","invalid literal for int() with base 10: 'a' error\n","Next entry.\n","\n","The entry is 0\n","division by zero error\n","Next entry.\n","\n","The entry is 2\n","The reciprocal of 2 is 0.5\n"]}]},{"cell_type":"markdown","source":["Whenever we wright program, the portion of program which can cause exception is placed inside the try block. If no exception is occurs, except block is skipped and normal flow continues. But if any exception occurs, it is handled by except block."],"metadata":{"id":"vXCjzzkWFdY-"}},{"cell_type":"code","source":["# import module sys to get the type of exception\n","import sys\n","randomList = ['a', 0, 2]\n","\n","for entry in randomList:\n","    try:\n","        print(\"The entry is\", entry)\n","        r = 1/int(entry)\n","        break\n","    except Exception as e:\n","        print(\"Oops!\", e ,\"occurred.\")\n","        print(\"Next entry.\")\n","        print()\n","\n","print(\"The reciprocal of\", entry, \"is\", r)"],"metadata":{"colab":{"base_uri":"https://localhost:8080/"},"id":"m5bu1OsBFuWL","executionInfo":{"status":"ok","timestamp":1650980273343,"user_tz":-330,"elapsed":480,"user":{"displayName":"Santhosh Kumar","userId":"02779163303914785334"}},"outputId":"25e04fc2-7de4-4f12-b43a-ecbd825648b2"},"execution_count":null,"outputs":[{"output_type":"stream","name":"stdout","text":["The entry is a\n","Oops! invalid literal for int() with base 10: 'a' occurred.\n","Next entry.\n","\n","The entry is 0\n","Oops! division by zero occurred.\n","Next entry.\n","\n","The entry is 2\n","The reciprocal of 2 is 0.5\n"]}]},{"cell_type":"markdown","source":["**Catching Specific Exceptions in Python**\n","\n","In the above example, except block catches all exceptions and handles all cases in same way. This is not good programming practice.\n","\n","A try clause may contain any number of except clauses to handle different exceptions, however, only one will be executed in case an exception occurs.\n","Multiple exceptions can be specified in an except clause using a tuple of values. Here is an example of pseudocode."],"metadata":{"id":"qOckophsGKtK"}},{"cell_type":"code","source":["try:\n","    # do something\n","    pass\n","except ValueError:\n","    # handle ValueError exception\n","    pass\n","except (TypeError, ZeroDivisionError):\n","    # handle multiple exceptions\n","    # TypeError and ZeroDivisionError\n","    pass\n","except:\n","    # handle all other exceptions\n","    pass"],"metadata":{"id":"yhFrQjgHGsYC"},"execution_count":null,"outputs":[]},{"cell_type":"markdown","source":["**Raising Exceptions in Python**\n","\n","In Python programming, using `raise keyword` we can raise exceptions. We can optionally pass values to the exception to clarify why that exception was raised.\n","\n","In below example we are passing ```It is not a positive number!``` value to exception clause using raise keyword."],"metadata":{"id":"N_3K3GkoHzwT"}},{"cell_type":"code","source":["try:\n","    a = int(input(\"Enter a positive integer: \"))\n","    if a <= 0:\n","        raise ValueError(\"It is not a positive number!\")\n","except ValueError as ve:\n","    print(ve)"],"metadata":{"colab":{"base_uri":"https://localhost:8080/"},"id":"w3liTpatH-P7","executionInfo":{"status":"ok","timestamp":1696499634759,"user_tz":-330,"elapsed":1732,"user":{"displayName":"Santhosh Kumar K S","userId":"03737205911667751064"}},"outputId":"af96af46-6286-463d-fd77-341960178a64"},"execution_count":3,"outputs":[{"output_type":"stream","name":"stdout","text":["Enter a positive integer: 0\n","It is not a positive number!\n"]}]},{"cell_type":"markdown","source":["**Python try with else clause**\n","\n","If we want to run certain block of code if exception is not occured in try block. We use else keyword with try statement in order to run certain code if try block runs smoothly."],"metadata":{"id":"jd8dqoO4I1WV"}},{"cell_type":"code","source":["# program to print the reciprocal of even numberss\n","try:\n","    num = int(input(\"Enter a number: \"))\n","    assert num % 2 == 0\n","except:\n","    print(\"Not an even number!\")\n","else:\n","    reciprocal = 1/num\n","    print(reciprocal)"],"metadata":{"colab":{"base_uri":"https://localhost:8080/"},"id":"975tYvUFI9KG","executionInfo":{"status":"ok","timestamp":1659511742653,"user_tz":-330,"elapsed":3795,"user":{"displayName":"Santhosh Kumar","userId":"02779163303914785334"}},"outputId":"eac8400e-b393-428e-af58-956d07690dea"},"execution_count":null,"outputs":[{"output_type":"stream","name":"stdout","text":["Enter a number: 2\n","0.5\n"]}]},{"cell_type":"code","source":["# program to print the reciprocal of even numbers\n","try:\n","    num = int(input(\"Enter a number: \"))\n","    assert num % 2 == 0\n","except:\n","    print(\"Not an even number!\")\n","else:\n","    reciprocal = 1/num\n","    print(reciprocal)"],"metadata":{"colab":{"base_uri":"https://localhost:8080/"},"id":"ndG7KF60m8Gr","executionInfo":{"status":"ok","timestamp":1659512631325,"user_tz":-330,"elapsed":5294,"user":{"displayName":"Santhosh Kumar","userId":"02779163303914785334"}},"outputId":"7ce355bd-4768-4533-ef2e-4cd33e4a09e4"},"execution_count":null,"outputs":[{"output_type":"stream","name":"stdout","text":["Enter a number: 3\n","0.3333333333333333\n"]}]},{"cell_type":"markdown","source":["**Python try...finally**\n","\n","The try statement in Python can have an optional finally clause. Regardless of whether an exception occurred or not, this clause is will be executed.\n","This clause is typically used to release external resources, such as when dealing with a file or connecting to data centre over the network.\n","\n","In all these circumstances, whether exception occurs or not we must clean up the resource. These type actions like closing file or disconnecting from network are performed in the finally clause to guarantee the execution."],"metadata":{"id":"HZzxHZvgJUhq"}},{"cell_type":"code","source":["try:\n","    fb = open(\"test.txt\",mode = 'w',encoding = 'utf-8')\n","    # perform file operations\n","except Exception as e:\n","    print(e)\n","finally:\n","    fb.close()"],"metadata":{"id":"-t__owjTJfRN"},"execution_count":null,"outputs":[]},{"cell_type":"markdown","source":["Else Block :    \n","\n","1. This block runs when try block runs smoothly.\n","\n","2. This block is used when we want to run certain code if try block executes without any error.\n","\n","3. This block is used with try block and except block.\n","\n","Finally Block :    \n","\n","1. This block runs no matter whether the program run with or eithout error.\n","\n","2. Normally this block is used to release the resources.\n","\n","3. Finally can be used either try block or try..except block.\n","\n"],"metadata":{"id":"UKfyp4cpoSCh"}}]}